Workbook
Name ワンポイントタグ: テーブル1[ワンポイントタグ]
Name 種族タグ: テーブル1[種族タグ]
Name 小物タグ: テーブル1[小物タグ]
Name 職業タグ: テーブル1[職業タグ]

Sheet キャラ情報
A1: 番号 | B1: 画像 | C1: 名前 | D1: なまえ | E1: Name | F1: リンク | G1: 作品タグ | H1: 性別 | I1: 種族タグ | J1: 職業タグ | K1: 小物タグ | L1: ワンポイントタグ | M1: グッズ許可・許可 | N1: 描画状況 | O1: 列1 | P1: 列2 | Q1: 乱数A | R1: 投稿状況 | S1: 乱数B | T1: |画像 | U1: |名前 | V1: |なまえ | W1: |Name | X1: |キャラクター情報リンク|
A2: 1 | B2: =SUBSTITUTE(SUBSTITUTE(SUBSTITUTE(SUBSTITUTE(SUBSTITUTE(SUBSTITUTE(SUBSTITUTE(SUBSTITUTE(LOWER(テーブル1[[#This Row],[Name]])," ","-"),".","-"),"&","-"),"_","-"),"・","-"),"=","-"),"--","-"),"--","-") -> akagane-fuyo | C2: 赤鐘芙蓉 | D2: あかがね ふよう | E2: Akagane Fuyo | F2: https://mitoristu.wixsite.com/kousaibako | G2: #虹彩箱 | H2: 女性 | I2: 鬼 | L2: 尖耳 | M2: 〇 / 不要 | N2: 済 | O2: =テーブル1[[#This Row],[リンク]]&テーブル1[[#This Row],[描画状況]] -> https://mitoristu.wixsite.com/kousaibako済 | P2: =1-(COUNTIF(O:O,_xlfn.TEXTJOIN(",",TRUE,テーブル1[[#This Row],[リンク]],テーブル1[[#This Row],[描画状況]]))/COUNTIF(F:F,テーブル1[[#This Row],[リンク]])) -> 1 | Q2: =IFERROR(IF(テーブル1[[#This Row],[描画状況]]="",RAND()+(テーブル1[[#This Row],[列2]]*100),""),RAND()) | R2: 済 | S2: =IF(AND(テーブル1[[#This Row],[描画状況]]="済",テーブル1[[#This Row],[投稿状況]]=""),RAND(),"") | T2: ="|&image("&テーブル1[[#This Row],[画像]]&".png,width=100,height=100)" -> |&image(akagane-fuyo.png,width=100,height=100) | U2: ="|MIDDLE:​"&テーブル1[[#This Row],[名前]] -> |MIDDLE:​赤鐘芙蓉 | V2: ="|MIDDLE:​"&テーブル1[[#This Row],[なまえ]] -> |MIDDLE:​あかがね ふよう | W2: ="|MIDDLE:​"&テーブル1[[#This Row],[Name]] -> |MIDDLE:​Akagane Fuyo | X2: ="|MIDDLE:​&link(配布所はこちら){​"&テーブル1[[#This Row],[リンク]]&"}|" -> |MIDDLE:​&link(配布所はこちら){​https://mitoristu.wixsite.com/kousaibako}|
A3: 2 | B3: =SUBSTITUTE(SUBSTITUTE(SUBSTITUTE(SUBSTITUTE(SUBSTITUTE(SUBSTITUTE(SUBSTITUTE(SUBSTITUTE(LOWER(テーブル1[[#This Row],[Name]])," ","-"),".","-"),"&","-"),"_","-"),"・","-"),"=","-"),"--","-"),"--","-") -> azumayatei-kyuichi | C3: 東屋亭久一 | D3: あずまやてい きゅういち | E3: Azumayatei Kyuichi | F3: https://lit.link/sereinrain | G3: #東屋でお茶でも | H3: 男性 | I3: 人間 | J3: 学者 | K3: 眼鏡 | L3: インナーカラー|片目隠れ | N3: 済 | O3: =テーブル1[[#This Row],[リンク]]&テーブル1[[#This Row],[描画状況]] -> https://lit.link/sereinrain済 | P3: =1-(COUNTIF(O:O,_xlfn.TEXTJOIN(",",TRUE,テーブル1[[#This Row],[リンク]],テーブル1[[#This Row],[描画状況]]))/COUNTIF(F:F,テーブル1[[#This Row],[リンク]])) -> 1 | Q3: =IFERROR(IF(テーブル1[[#This Row],[描画状況]]="",RAND()+(テーブル1[[#This Row],[列2]]*100),""),RAND()) | R3: 済 | S3: =IF(AND(テーブル1[[#This Row],[描画状況]]="済",テーブル1[[#This Row],[投稿状況]]=""),RAND(),"") | T3: ="|&image("&テーブル1[[#This Row],[画像]]&".png,width=100,height=100)" -> |&image(azumayatei-kyuichi.png,width=100,height=100) | U3: ="|MIDDLE:​"&テーブル1[[#This Row],[名前]] -> |MIDDLE:​東屋亭久一 | V3: ="|MIDDLE:​"&テーブル1[[#This Row],[なまえ]] -> |MIDDLE:​あずまやてい きゅういち | W3: ="|MIDDLE:​"&テーブル1[[#This Row],[Name]] -> |MIDDLE:​Azumayatei Kyuichi | X3: ="|MIDDLE:​&link(配布所はこちら){​"&テーブル1[[#This Row],[リンク]]&"}|" -> |MIDDLE:​&link(配布所はこちら){​https://lit.link/sereinrain}|
A4: 3 | B4: =SUBSTITUTE(SUBSTITUTE(SUBSTITUTE(SUBSTITUTE(SUBSTITUTE(SUBSTITUTE(SUBSTITUTE(SUBSTITUTE(LOWER(テーブル1[[#This Row],[Name]])," ","-"),".","-"),"&","-"),"_","-"),"・","-"),"=","-"),"--","-"),"--","-") -> acetate | C4: アセテート | D4: あせてーと | E4: Acetate | F4: https://cloudcatch1224.wixsite.com/godsfoot | G4: #神様の足元 | H4: 男性 | I4: 人間|機械 | J4: 機械整備士 | L4: 角(ツノ)|羽|尻尾 | M4: 〇 / 必要 | N4: 済 | O4: =テーブル1[[#This Row],[リンク]]&テーブル1[[#This Row],[描画状況]] -> https://cloudcatch1224.wixsite.com/godsfoot済 | P4: =1-(COUNTIF(O:O,_xlfn.TEXTJOIN(",",TRUE,テーブル1[[#This Row],[リンク]],テーブル1[[#This Row],[描画状況]]))/COUNTIF(F:F,テーブル1[[#This Row],[リンク]])) -> 1 | Q4: =IFERROR(IF(テーブル1[[#This Row],[描画状況]]="",RAND()+(テーブル1[[#This Row],[列2]]*100),""),RAND()) | R4: 済 | S4: =IF(AND(テーブル1[[#This Row],[描画状況]]="済",テーブル1[[#This Row],[投稿状況]]=""),RAND(),"") | T4: ="|&image("&テーブル1[[#This Row],[画像]]&".png,width=100,height=100)" -> |&image(acetate.png,width=100,height=100) | U4: ="|MIDDLE:​"&テーブル1[[#This Row],[名前]] -> |MIDDLE:​アセテート | V4: ="|MIDDLE:​"&テーブル1[[#This Row],[なまえ]] -> |MIDDLE:​あせてーと | W4: ="|MIDDLE:​"&テーブル1[[#This Row],[Name]] -> |MIDDLE:​Acetate | X4: ="|MIDDLE:​&link(配布所はこちら){​"&テーブル1[[#This Row],[リンク]]&"}|" -> |MIDDLE:​&link(配布所はこちら){​https://cloudcatch1224.wixsite.com/godsfoot}|
A5: 4 | B5: =SUBSTITUTE(SUBSTITUTE(SUBSTITUTE(SUBSTITUTE(SUBSTITUTE(SUBSTITUTE(SUBSTITUTE(SUBSTITUTE(LOWER(テーブル1[[#This Row],[Name]])," ","-"),".","-"),"&","-"),"_","-"),"・","-"),"=","-"),"--","-"),"--","-") -> adachi-rei | C5: 足立レイ | D5: あだち れい | E5: Adachi Rei | F5: https://mechanicalgirl.jp | G5: #足立レイ | H5: 女性 | I5: 機械 | K5: イヤーユニット | N5: 済 | O5: =テーブル1[[#This Row],[リンク]]&テーブル1[[#This Row],[描画状況]] -> https://mechanicalgirl.jp済 | P5: =1-(COUNTIF(O:O,_xlfn.TEXTJOIN(",",TRUE,テーブル1[[#This Row],[リンク]],テーブル1[[#This Row],[描画状況]]))/COUNTIF(F:F,テーブル1[[#This Row],[リンク]])) -> 1 | Q5: =IFERROR(IF(テーブル1[[#This Row],[描画状況]]="",RAND()+(テーブル1[[#This Row],[列2]]*100),""),RAND()) | R5: 済 | S5: =IF(AND(テーブル1[[#This Row],[描画状況]]="済",テーブル1[[#This Row],[投稿状況]]=""),RAND(),"") | T5: ="|&image("&テーブル1[[#This Row],[画像]]&".png,width=100,height=100)" -> |&image(adachi-rei.png,width=100,height=100) | U5: ="|MIDDLE:​"&テーブル1[[#This Row],[名前]] -> |MIDDLE:​足立レイ | V5: ="|MIDDLE:​"&テーブル1[[#This Row],[なまえ]] -> |MIDDLE:​あだち れい | W5: ="|MIDDLE:​"&テーブル1[[#This Row],[Name]] -> |MIDDLE:​Adachi Rei | X5: ="|MIDDLE:​&link(配布所はこちら){​"&テーブル1[[#This Row],[リンク]]&"}|" -> |MIDDLE:​&link(配布所はこちら){​https://mechanicalgirl.jp}|
A6: 5 | B6: =SUBSTITUTE(SUBSTITUTE(SUBSTITUTE(SUBSTITUTE(SUBSTITUTE(SUBSTITUTE(SUBSTITUTE(SUBSTITUTE(LOWER(テーブル1[[#This Row],[Name]])," ","-"),".","-"),"&","-"),"_","-"),"・","-"),"=","-"),"--","-"),"--","-") -> atorine-hiwa | C6: 花鶏音ひわ | D6: あとりね ひわ | E6: Atorine Hiwa | F6: https://torinosu-hikikomori.jimdofree.com | G6: #ひわわーアラート | H6: 女性 | I6: 鳥 | K6: マスク | L6: 羽 | N6: 済 | O6: =テーブル1[[#This Row],[リンク]]&テーブル1[[#This Row],[描画状況]] -> https://torinosu-hikikomori.jimdofree.com済 | P6: =1-(COUNTIF(O:O,_xlfn.TEXTJOIN(",",TRUE,テーブル1[[#This Row],[リンク]],テーブル1[[#This Row],[描画状況]]))/COUNTIF(F:F,テーブル1[[#This Row],[リンク]])) -> 1 | Q6: =IFERROR(IF(テーブル1[[#This Row],[描画状況]]="",RAND()+(テーブル1[[#This Row],[列2]]*100),""),RAND()) | R6: 済 | S6: =IF(AND(テーブル1[[#This Row],[描画状況]]="済",テーブル1[[#This Row],[投稿状況]]=""),RAND(),"") | T6: ="|&image("&テーブル1[[#This Row],[画像]]&".png,width=100,height=100)" -> |&image(atorine-hiwa.png,width=100,height=100) | U6: ="|MIDDLE:​"&テーブル1[[#This Row],[名前]] -> |MIDDLE:​花鶏音ひわ | V6: ="|MIDDLE:​"&テーブル1[[#This Row],[なまえ]] -> |MIDDLE:​あとりね ひわ | W6: ="|MIDDLE:​"&テーブル1[[#This Row],[Name]] -> |MIDDLE:​Atorine Hiwa | X6: ="|MIDDLE:​&link(配布所はこちら){​"&テーブル1[[#This Row],[リンク]]&"}|" -> |MIDDLE:​&link(配布所はこちら){​https://torinosu-hikikomori.jimdofree.com}|
A7: 6 | B7: =SUBSTITUTE(SUBSTITUTE(SUBSTITUTE(SUBSTITUTE(SUBSTITUTE(SUBSTITUTE(SUBSTITUTE(SUBSTITUTE(LOWER(テーブル1[[#This Row],[Name]])," ","-"),".","-"),"&","-"),"_","-"),"・","-"),"=","-"),"--","-"),"--","-") -> adol | C7: Adol | D7: あどる | E7: Adol | F7: https://kuroi9603.wixsite.com/delu-lab-south | G7: #でるらぼ | H7: 女性 | I7: 人間 | N7: 済 | O7: =テーブル1[[#This Row],[リンク]]&テーブル1[[#This Row],[描画状況]] -> https://kuroi9603.wixsite.com/delu-lab-south済 | P7: =1-(COUNTIF(O:O,_xlfn.TEXTJOIN(",",TRUE,テーブル1[[#This Row],[リンク]],テーブル1[[#This Row],[描画状況]]))/COUNTIF(F:F,テーブル1[[#This Row],[リンク]])) -> 1 | Q7: =IFERROR(IF(テーブル1[[#This Row],[描画状況]]="",RAND()+(テーブル1[[#This Row],[列2]]*100),""),RAND()) | R7: 済 | S7: =IF(AND(テーブル1[[#This Row],[描画状況]]="済",テーブル1[[#This Row],[投稿状況]]=""),RAND(),"") | T7: ="|&image("&テーブル1[[#This Row],[画像]]&".png,width=100,height=100)" -> |&image(adol.png,width=100,height=100) | U7: ="|MIDDLE:​"&テーブル1[[#This Row],[名前]] -> |MIDDLE:​Adol | V7: ="|MIDDLE:​"&テーブル1[[#This Row],[なまえ]] -> |MIDDLE:​あどる | W7: ="|MIDDLE:​"&テーブル1[[#This Row],[Name]] -> |MIDDLE:​Adol | X7: ="|MIDDLE:​&link(配布所はこちら){​"&テーブル1[[#This Row],[リンク]]&"}|" -> |MIDDLE:​&link(配布所はこちら){​https://kuroi9603.wixsite.com/delu-lab-south}|
A8: 7 | B8: =SUBSTITUTE(SUBSTITUTE(SUBSTITUTE(SUBSTITUTE(SUBSTITUTE(SUBSTITUTE(SUBSTITUTE(SUBSTITUTE(LOWER(テーブル1[[#This Row],[Name]])," ","-"),".","-"),"&","-"),"_","-"),"・","-"),"=","-"),"--","-"),"--","-") -> anima-raituhatto | C8: アニマ・ライツハット | D8: あにま らいつはっと | E8: Anima Raituhatto | F8: https://seirentoybox.jimdofree.com | G8: #セレソー作 | H8: 無性別 | I8: バーチャル | K8: 眼鏡 | L8: オッドアイ | M8: 〇 / 不要 | N8: 済 | O8: =テーブル1[[#This Row],[リンク]]&テーブル1[[#This Row],[描画状況]] -> https://seirentoybox.jimdofree.com済 | P8: =1-(COUNTIF(O:O,_xlfn.TEXTJOIN(",",TRUE,テーブル1[[#This Row],[リンク]],テーブル1[[#This Row],[描画状況]]))/COUNTIF(F:F,テーブル1[[#This Row],[リンク]])) -> 1 | Q8: =IFERROR(IF(テーブル1[[#This Row],[描画状況]]="",RAND()+(テーブル1[[#This Row],[列2]]*100),""),RAND()) | R8: 済 | S8: =IF(AND(テーブル1[[#This Row],[描画状況]]="済",テーブル1[[#This Row],[投稿状況]]=""),RAND(),"") | T8: ="|&image("&テーブル1[[#This Row],[画像]]&".png,width=100,height=100)" -> |&image(anima-raituhatto.png,width=100,height=100) | U8: ="|MIDDLE:​"&テーブル1[[#This Row],[名前]] -> |MIDDLE:​アニマ・ライツハット | V8: ="|MIDDLE:​"&テーブル1[[#This Row],[なまえ]] -> |MIDDLE:​あにま らいつはっと | W8: ="|MIDDLE:​"&テーブル1[[#This Row],[Name]] -> |MIDDLE:​Anima Raituhatto | X8: ="|MIDDLE:​&link(配布所はこちら){​"&テーブル1[[#This Row],[リンク]]&"}|" -> |MIDDLE:​&link(配布所はこちら){​https://seirentoybox.jimdofree.com}|
A9: 8 | B9: =SUBSTITUTE(SUBSTITUTE(SUBSTITUTE(SUBSTITUTE(SUBSTITUTE(SUBSTITUTE(SUBSTITUTE(SUBSTITUTE(LOWER(テーブル1[[#This Row],[Name]])," ","-"),".","-"),"&","-"),"_","-"),"・","-"),"=","-"),"--","-"),"--","-") -> amatsuka-fuawa | C9: 天使ふあわ | D9: あまつか ふあわ | E9: Amatsuka Fuawa | F9: https://utausuzuminnya.jimdofree.com | G9: #ふあわあーと | H9: 女性 | I9: 人間|天使 | L9: 羽 | N9: 済 | O9: =テーブル1[[#This Row],[リンク]]&テーブル1[[#This Row],[描画状況]] -> https://utausuzuminnya.jimdofree.com済 | P9: =1-(COUNTIF(O:O,_xlfn.TEXTJOIN(",",TRUE,テーブル1[[#This Row],[リンク]],テーブル1[[#This Row],[描画状況]]))/COUNTIF(F:F,テーブル1[[#This Row],[リンク]])) -> 1 | Q9: =IFERROR(IF(テーブル1[[#This Row],[描画状況]]="",RAND()+(テーブル1[[#This Row],[列2]]*100),""),RAND()) | R9: 済 | S9: =IF(AND(テーブル1[[#This Row],[描画状況]]="済",テーブル1[[#This Row],[投稿状況]]=""),RAND(),"") | T9: ="|&image("&テーブル1[[#This Row],[画像]]&".png,width=100,height=100)" -> |&image(amatsuka-fuawa.png,width=100,height=100) | U9: ="|MIDDLE:​"&テーブル1[[#This Row],[名前]] -> |MIDDLE:​天使ふあわ | V9: ="|MIDDLE:​"&テーブル1[[#This Row],[なまえ]] -> |MIDDLE:​あまつか ふあわ | W9: ="|MIDDLE:​"&テーブル1[[#This Row],[Name]] -> |MIDDLE:​Amatsuka Fuawa | X9: ="|MIDDLE:​&link(配布所はこちら){​"&テーブル1[[#This Row],[リンク]]&"}|" -> |MIDDLE:​&link(配布所はこちら){​https://utausuzuminnya.jimdofree.com}|
A10: 9 | B10: =SUBSTITUTE(SUBSTITUTE(SUBSTITUTE(SUBSTITUTE(SUBSTITUTE(SUBSTITUTE(SUBSTITUTE(SUBSTITUTE(LOWER(テーブル1[[#This Row],[Name]])," ","-"),".","-"),"&","-"),"_","-"),"・","-"),"=","-"),"--","-"),"--","-") -> amane-usagi | C10: 雨音うさぎ | D10: あまね うさぎ | E10: Amane Usagi | F10: https://sabaneko.amebaownd.com | G10: #雨音うさぎ | H10: 女性 | I10: 人間 | K10: 動物 | L10: 渦巻き目、アホ毛 | N10: 済 | O10: =テーブル1[[#This Row],[リンク]]&テーブル1[[#This Row],[描画状況]] -> https://sabaneko.amebaownd.com済 | P10: =1-(COUNTIF(O:O,_xlfn.TEXTJOIN(",",TRUE,テーブル1[[#This Row],[リンク]],テーブル1[[#This Row],[描画状況]]))/COUNTIF(F:F,テーブル1[[#This Row],[リンク]])) -> 1 | Q10: =IFERROR(IF(テーブル1[[#This Row],[描画状況]]="",RAND()+(テーブル1[[#This Row],[列2]]*100),""),RAND()) | R10: 済 | S10: =IF(AND(テーブル1[[#This Row],[描画状況]]="済",テーブル1[[#This Row],[投稿状況]]=""),RAND(),"") | T10: ="|&image("&テーブル1[[#This Row],[画像]]&".png,width=100,height=100)" -> |&image(amane-usagi.png,width=100,height=100) | U10: ="|MIDDLE:​"&テーブル1[[#This Row],[名前]] -> |MIDDLE:​雨音うさぎ | V10: ="|MIDDLE:​"&テーブル1[[#This Row],[なまえ]] -> |MIDDLE:​あまね うさぎ | W10: ="|MIDDLE:​"&テーブル1[[#This Row],[Name]] -> |MIDDLE:​Amane Usagi | X10: ="|MIDDLE:​&link(配布所はこちら){​"&テーブル1[[#This Row],[リンク]]&"}|" -> |MIDDLE:​&link(配布所はこちら){​https://sabaneko.amebaownd.com}|
A11: 10 | B11: =SUBSTITUTE(SUBSTITUTE(SUBSTITUTE(SUBSTITUTE(SUBSTITUTE(SUBSTITUTE(SUBSTITUTE(SUBSTITUTE(LOWER(テーブル1[[#This Row],[Name]])," ","-"),".","-"),"&","-"),"_","-"),"・","-"),"=","-"),"--","-"),"--","-") -> ayashiki | C11: 怪子奇 | D11: あやしき | E11: Ayashiki | F11: https://inudanuki.wixsite.com/gottaniomotyabako | G11: #煮バコ | H11: 男性 | I11: 故人|幽霊 | L11: ツートンカラー | N11: 済 | O11: =テーブル1[[#This Row],[リンク]]&テーブル1[[#This Row],[描画状況]] -> https://inudanuki.wixsite.com/gottaniomotyabako済 | P11: =1-(COUNTIF(O:O,_xlfn.TEXTJOIN(",",TRUE,テーブル1[[#This Row],[リンク]],テーブル1[[#This Row],[描画状況]]))/COUNTIF(F:F,テーブル1[[#This Row],[リンク]])) -> 1 | Q11: =IFERROR(IF(テーブル1[[#This Row],[描画状況]]="",RAND()+(テーブル1[[#This Row],[列2]]*100),""),RAND()) | R11: 済 | S11: =IF(AND(テーブル1[[#This Row],[描画状況]]="済",テーブル1[[#This Row],[投稿状況]]=""),RAND(),"") | T11: ="|&image("&テーブル1[[#This Row],[画像]]&".png,width=100,height=100)" -> |&image(ayashiki.png,width=100,height=100) | U11: ="|MIDDLE:​"&テーブル1[[#This Row],[名前]] -> |MIDDLE:​怪子奇 | V11: ="|MIDDLE:​"&テーブル1[[#This Row],[なまえ]] -> |MIDDLE:​あやしき | W11: ="|MIDDLE:​"&テーブル1[[#This Row],[Name]] -> |MIDDLE:​Ayashiki | X11: ="|MIDDLE:​&link(配布所はこちら){​"&テーブル1[[#This Row],[リンク]]&"}|" -> |MIDDLE:​&link(配布所はこちら){​https://inudanuki.wixsite.com/gottaniomotyabako}|
A12: 11 | B12: =SUBSTITUTE(SUBSTITUTE(SUBSTITUTE(SUBSTITUTE(SUBSTITUTE(SUBSTITUTE(SUBSTITUTE(SUBSTITUTE(LOWER(テーブル1[[#This Row],[Name]])," ","-"),".","-"),"&","-"),"_","-"),"・","-"),"=","-"),"--","-"),"--","-") -> utakata-tsumugi | C12: 泡沫紬 | D12: うたかた つむぎ | E12: Utakata Tsumugi | F12: https://tourist100f.wixsite.com/utakata-kosyo | G12: #泡沫古書店 | H12: 女性 | I12: 人間 | J12: 書店員 | K12: 眼鏡 | N12: 済 | O12: =テーブル1[[#This Row],[リンク]]&テーブル1[[#This Row],[描画状況]] -> https://tourist100f.wixsite.com/utakata-kosyo済 | P12: =1-(COUNTIF(O:O,_xlfn.TEXTJOIN(",",TRUE,テーブル1[[#This Row],[リンク]],テーブル1[[#This Row],[描画状況]]))/COUNTIF(F:F,テーブル1[[#This Row],[リンク]])) -> 1 | Q12: =IFERROR(IF(テーブル1[[#This Row],[描画状況]]="",RAND()+(テーブル1[[#This Row],[列2]]*100),""),RAND()) | R12: 済 | S12: =IF(AND(テーブル1[[#This Row],[描画状況]]="済",テーブル1[[#This Row],[投稿状況]]=""),RAND(),"") | T12: ="|&image("&テーブル1[[#This Row],[画像]]&".png,width=100,height=100)" -> |&image(utakata-tsumugi.png,width=100,height=100) | U12: ="|MIDDLE:​"&テーブル1[[#This Row],[名前]] -> |MIDDLE:​泡沫紬 | V12: ="|MIDDLE:​"&テーブル1[[#This Row],[なまえ]] -> |MIDDLE:​うたかた つむぎ | W12: ="|MIDDLE:​"&テーブル1[[#This Row],[Name]] -> |MIDDLE:​Utakata Tsumugi | X12: ="|MIDDLE:​&link(配布所はこちら){​"&テーブル1[[#This Row],[リンク]]&"}|" -> |MIDDLE:​&link(配布所はこちら){​https://tourist100f.wixsite.com/utakata-kosyo}|
A13: 12 | B13: =SUBSTITUTE(SUBSTITUTE(SUBSTITUTE(SUBSTITUTE(SUBSTITUTE(SUBSTITUTE(SUBSTITUTE(SUBSTITUTE(LOWER(テーブル1[[#This Row],[Name]])," ","-"),".","-"),"&","-"),"_","-"),"・","-"),"=","-"),"--","-"),"--","-") -> utane-uta(defoko) | C13: 唄音ウタ(デフォ子) | D13: うたね うた(でふぉこ) | E13: Utane Uta(Defoko) | F13: - | G13: #デフォ子 | H13: 女性 | K13: ヘッドセット | M13: 〇 / 不要 | N13: 済 | O13: =テーブル1[[#This Row],[リンク]]&テーブル1[[#This Row],[描画状況]] -> -済 | P13: =1-(COUNTIF(O:O,_xlfn.TEXTJOIN(",",TRUE,テーブル1[[#This Row],[リンク]],テーブル1[[#This Row],[描画状況]]))/COUNTIF(F:F,テーブル1[[#This Row],[リンク]])) -> 1 | Q13: =IFERROR(IF(テーブル1[[#This Row],[描画状況]]="",RAND()+(テーブル1[[#This Row],[列2]]*100),""),RAND()) | R13: 済 | S13: =IF(AND(テーブル1[[#This Row],[描画状況]]="済",テーブル1[[#This Row],[投稿状況]]=""),RAND(),"") | T13: ="|&image("&テーブル1[[#This Row],[画像]]&".png,width=100,height=100)" -> |&image(utane-uta(defoko).png,width=100,height=100) | U13: ="|MIDDLE:​"&テーブル1[[#This Row],[名前]] -> |MIDDLE:​唄音ウタ(デフォ子) | V13: ="|MIDDLE:​"&テーブル1[[#This Row],[なまえ]] -> |MIDDLE:​うたね うた(でふぉこ) | W13: ="|MIDDLE:​"&テーブル1[[#This Row],[Name]] -> |MIDDLE:​Utane Uta(Defoko) | X13: ="|MIDDLE:​&link(配布所はこちら){​"&テーブル1[[#This Row],[リンク]]&"}|" -> |MIDDLE:​&link(配布所はこちら){​-}|
A14: 13 | B14: =SUBSTITUTE(SUBSTITUTE(SUBSTITUTE(SUBSTITUTE(SUBSTITUTE(SUBSTITUTE(SUBSTITUTE(SUBSTITUTE(LOWER(テーブル1[[#This Row],[Name]])," ","-"),".","-"),"&","-"),"_","-"),"・","-"),"=","-"),"--","-"),"--","-") -> uruya | C14: URUYA | D14: うるや | E14: Uruya | F14: https://sites.google.com/view/tokakobo | G14: #透歌工房 | H14: 女性 | I14: フィギュア | L14: 尻尾 | N14: 済 | O14: =テーブル1[[#This Row],[リンク]]&テーブル1[[#This Row],[描画状況]] -> https://sites.google.com/view/tokakobo済 | P14: =1-(COUNTIF(O:O,_xlfn.TEXTJOIN(",",TRUE,テーブル1[[#This Row],[リンク]],テーブル1[[#This Row],[描画状況]]))/COUNTIF(F:F,テーブル1[[#This Row],[リンク]])) -> 1 | Q14: =IFERROR(IF(テーブル1[[#This Row],[描画状況]]="",RAND()+(テーブル1[[#This Row],[列2]]*100),""),RAND()) | R14: 済 | S14: =IF(AND(テーブル1[[#This Row],[描画状況]]="済",テーブル1[[#This Row],[投稿状況]]=""),RAND(),"") | T14: ="|&image("&テーブル1[[#This Row],[画像]]&".png,width=100,height=100)" -> |&image(uruya.png,width=100,height=100) | U14: ="|MIDDLE:​"&テーブル1[[#This Row],[名前]] -> |MIDDLE:​URUYA | V14: ="|MIDDLE:​"&テーブル1[[#This Row],[なまえ]] -> |MIDDLE:​うるや | W14: ="|MIDDLE:​"&テーブル1[[#This Row],[Name]] -> |MIDDLE:​Uruya | X14: ="|MIDDLE:​&link(配布所はこちら){​"&テーブル1[[#This Row],[リンク]]&"}|" -> |MIDDLE:​&link(配布所はこちら){​https://sites.google.com/view/tokakobo}|
A15: 14 | B15: =SUBSTITUTE(SUBSTITUTE(SUBSTITUTE(SUBSTITUTE(SUBSTITUTE(SUBSTITUTE(SUBSTITUTE(SUBSTITUTE(LOWER(テーブル1[[#This Row],[Name]])," ","-"),".","-"),"&","-"),"_","-"),"・","-"),"=","-"),"--","-"),"--","-") -> oroku-korokuro | C15: オーロク&小六郎 | D15: おーろく & ころくろう | E15: Oroku & korokuro | F15: https://torinosu-hikikomori.jimdofree.com | G15: #ひわわーアラート | H15: 男性 | I15: 人間|人形 | J15: 腹話術師 | L15: 両目隠れ | N15: 済 | O15: =テーブル1[[#This Row],[リンク]]&テーブル1[[#This Row],[描画状況]] -> https://torinosu-hikikomori.jimdofree.com済 | P15: =1-(COUNTIF(O:O,_xlfn.TEXTJOIN(",",TRUE,テーブル1[[#This Row],[リンク]],テーブル1[[#This Row],[描画状況]]))/COUNTIF(F:F,テーブル1[[#This Row],[リンク]])) -> 1 | Q15: =IFERROR(IF(テーブル1[[#This Row],[描画状況]]="",RAND()+(テーブル1[[#This Row],[列2]]*100),""),RAND()) | R15: 済 | S15: =IF(AND(テーブル1[[#This Row],[描画状況]]="済",テーブル1[[#This Row],[投稿状況]]=""),RAND(),"") | T15: ="|&image("&テーブル1[[#This Row],[画像]]&".png,width=100,height=100)" -> |&image(oroku-korokuro.png,width=100,height=100) | U15: ="|MIDDLE:​"&テーブル1[[#This Row],[名前]] -> |MIDDLE:​オーロク&小六郎 | V15: ="|MIDDLE:​"&テーブル1[[#This Row],[なまえ]] -> |MIDDLE:​おーろく & ころくろう | W15: ="|MIDDLE:​"&テーブル1[[#This Row],[Name]] -> |MIDDLE:​Oroku & korokuro | X15: ="|MIDDLE:​&link(配布所はこちら){​"&テーブル1[[#This Row],[リンク]]&"}|" -> |MIDDLE:​&link(配布所はこちら){​https://torinosu-hikikomori.jimdofree.com}|
A16: 15 | B16: =SUBSTITUTE(SUBSTITUTE(SUBSTITUTE(SUBSTITUTE(SUBSTITUTE(SUBSTITUTE(SUBSTITUTE(SUBSTITUTE(LOWER(テーブル1[[#This Row],[Name]])," ","-"),".","-"),"&","-"),"_","-"),"・","-"),"=","-"),"--","-"),"--","-") -> ohoshi | C16: お星 | D16: おほし | E16: Ohoshi | F16: https://ichistart.wixsite.com/official/respiaker | G16: #ichistar | H16: 女性 | I16: 天使 | J16: クリエイター | L16: メッシュ | M16: 〇 / 不要 | N16: 済 | O16: =テーブル1[[#This Row],[リンク]]&テーブル1[[#This Row],[描画状況]] -> https://ichistart.wixsite.com/official/respiaker済 | P16: =1-(COUNTIF(O:O,_xlfn.TEXTJOIN(",",TRUE,テーブル1[[#This Row],[リンク]],テーブル1[[#This Row],[描画状況]]))/COUNTIF(F:F,テーブル1[[#This Row],[リンク]])) -> 1 | Q16: =IFERROR(IF(テーブル1[[#This Row],[描画状況]]="",RAND()+(テーブル1[[#This Row],[列2]]*100),""),RAND()) | R16: 済 | S16: =IF(AND(テーブル1[[#This Row],[描画状況]]="済",テーブル1[[#This Row],[投稿状況]]=""),RAND(),"") | T16: ="|&image("&テーブル1[[#This Row],[画像]]&".png,width=100,height=100)" -> |&image(ohoshi.png,width=100,height=100) | U16: ="|MIDDLE:​"&テーブル1[[#This Row],[名前]] -> |MIDDLE:​お星 | V16: ="|MIDDLE:​"&テーブル1[[#This Row],[なまえ]] -> |MIDDLE:​おほし | W16: ="|MIDDLE:​"&テーブル1[[#This Row],[Name]] -> |MIDDLE:​Ohoshi | X16: ="|MIDDLE:​&link(配布所はこちら){​"&テーブル1[[#This Row],[リンク]]&"}|" -> |MIDDLE:​&link(配布所はこちら){​https://ichistart.wixsite.com/official/respiaker}|
A17: 16 | B17: =SUBSTITUTE(SUBSTITUTE(SUBSTITUTE(SUBSTITUTE(SUBSTITUTE(SUBSTITUTE(SUBSTITUTE(SUBSTITUTE(LOWER(テーブル1[[#This Row],[Name]])," ","-"),".","-"),"&","-"),"_","-"),"・","-"),"=","-"),"--","-"),"--","-") -> kagiai-aya | C17: 鍵合アヤ | D17: かぎあい あや | E17: Kagiai Aya | F17: https://vividseekers.utau.sorairomarch.com | G17: #そらいろマーチ | H17: 無性別 | I17: バーチャル | M17: 〇 / 不要 | N17: 済 | O17: =テーブル1[[#This Row],[リンク]]&テーブル1[[#This Row],[描画状況]] -> https://vividseekers.utau.sorairomarch.com済 | P17: =1-(COUNTIF(O:O,_xlfn.TEXTJOIN(",",TRUE,テーブル1[[#This Row],[リンク]],テーブル1[[#This Row],[描画状況]]))/COUNTIF(F:F,テーブル1[[#This Row],[リンク]])) -> 1 | Q17: =IFERROR(IF(テーブル1[[#This Row],[描画状況]]="",RAND()+(テーブル1[[#This Row],[列2]]*100),""),RAND()) | R17: 済 | S17: =IF(AND(テーブル1[[#This Row],[描画状況]]="済",テーブル1[[#This Row],[投稿状況]]=""),RAND(),"") | T17: ="|&image("&テーブル1[[#This Row],[画像]]&".png,width=100,height=100)" -> |&image(kagiai-aya.png,width=100,height=100) | U17: ="|MIDDLE:​"&テーブル1[[#This Row],[名前]] -> |MIDDLE:​鍵合アヤ | V17: ="|MIDDLE:​"&テーブル1[[#This Row],[なまえ]] -> |MIDDLE:​かぎあい あや | W17: ="|MIDDLE:​"&テーブル1[[#This Row],[Name]] -> |MIDDLE:​Kagiai Aya | X17: ="|MIDDLE:​&link(配布所はこちら){​"&テーブル1[[#This Row],[リンク]]&"}|" -> |MIDDLE:​&link(配布所はこちら){​https://vividseekers.utau.sorairomarch.com}|
A18: 17 | B18: =SUBSTITUTE(SUBSTITUTE(SUBSTITUTE(SUBSTITUTE(SUBSTITUTE(SUBSTITUTE(SUBSTITUTE(SUBSTITUTE(LOWER(テーブル1[[#This Row],[Name]])," ","-"),".","-"),"&","-"),"_","-"),"・","-"),"=","-"),"--","-"),"--","-") -> kagiai-suzu | C18: 鍵合スズ | D18: かぎあい すず | E18: Kagiai Suzu | F18: https://vividseekers.utau.sorairomarch.com | G18: #そらいろマーチ | H18: 無性別 | I18: バーチャル | J18: ヤンキー | M18: 〇 / 不要 | N18: 済 | O18: =テーブル1[[#This Row],[リンク]]&テーブル1[[#This Row],[描画状況]] -> https://vividseekers.utau.sorairomarch.com済 | P18: =1-(COUNTIF(O:O,_xlfn.TEXTJOIN(",",TRUE,テーブル1[[#This Row],[リンク]],テーブル1[[#This Row],[描画状況]]))/COUNTIF(F:F,テーブル1[[#This Row],[リンク]])) -> 1 | Q18: =IFERROR(IF(テーブル1[[#This Row],[描画状況]]="",RAND()+(テーブル1[[#This Row],[列2]]*100),""),RAND()) | R18: 済 | S18: =IF(AND(テーブル1[[#This Row],[描画状況]]="済",テーブル1[[#This Row],[投稿状況]]=""),RAND(),"") | T18: ="|&image("&テーブル1[[#This Row],[画像]]&".png,width=100,height=100)" -> |&image(kagiai-suzu.png,width=100,height=100) | U18: ="|MIDDLE:​"&テーブル1[[#This Row],[名前]] -> |MIDDLE:​鍵合スズ | V18: ="|MIDDLE:​"&テーブル1[[#This Row],[なまえ]] -> |MIDDLE:​かぎあい すず | W18: ="|MIDDLE:​"&テーブル1[[#This Row],[Name]] -> |MIDDLE:​Kagiai Suzu | X18: ="|MIDDLE:​&link(配布所はこちら){​"&テーブル1[[#This Row],[リンク]]&"}|" -> |MIDDLE:​&link(配布所はこちら){​https://vividseekers.utau.sorairomarch.com}|
A19: 18 | B19: =SUBSTITUTE(SUBSTITUTE(SUBSTITUTE(SUBSTITUTE(SUBSTITUTE(SUBSTITUTE(SUBSTITUTE(SUBSTITUTE(LOWER(テーブル1[[#This Row],[Name]])," ","-"),".","-"),"&","-"),"_","-"),"・","-"),"=","-"),"--","-"),"--","-") -> kakune-shanonn | C19: ​拡音シャノン | D19: かくね しゃのん | E19: Kakune Shanonn | F19: https://ameutaulii.wixsite.com/telepathycapsule | G19: #拡音シャノン | H19: 女性 | K19: ヘアピン|拡声器 | M19: 〇 / 必要 | N19: 済 | O19: =テーブル1[[#This Row],[リンク]]&テーブル1[[#This Row],[描画状況]] -> https://ameutaulii.wixsite.com/telepathycapsule済 | P19: =1-(COUNTIF(O:O,_xlfn.TEXTJOIN(",",TRUE,テーブル1[[#This Row],[リンク]],テーブル1[[#This Row],[描画状況]]))/COUNTIF(F:F,テーブル1[[#This Row],[リンク]])) -> 1 | Q19: =IFERROR(IF(テーブル1[[#This Row],[描画状況]]="",RAND()+(テーブル1[[#This Row],[列2]]*100),""),RAND()) | R19: 済 | S19: =IF(AND(テーブル1[[#This Row],[描画状況]]="済",テーブル1[[#This Row],[投稿状況]]=""),RAND(),"") | T19: ="|&image("&テーブル1[[#This Row],[画像]]&".png,width=100,height=100)" -> |&image(kakune-shanonn.png,width=100,height=100) | U19: ="|MIDDLE:​"&テーブル1[[#This Row],[名前]] -> |MIDDLE:​​拡音シャノン | V19: ="|MIDDLE:​"&テーブル1[[#This Row],[なまえ]] -> |MIDDLE:​かくね しゃのん | W19: ="|MIDDLE:​"&テーブル1[[#This Row],[Name]] -> |MIDDLE:​Kakune Shanonn | X19: ="|MIDDLE:​&link(配布所はこちら){​"&テーブル1[[#This Row],[リンク]]&"}|" -> |MIDDLE:​&link(配布所はこちら){​https://ameutaulii.wixsite.com/telepathycapsule}|
A20: 19 | B20: =SUBSTITUTE(SUBSTITUTE(SUBSTITUTE(SUBSTITUTE(SUBSTITUTE(SUBSTITUTE(SUBSTITUTE(SUBSTITUTE(LOWER(テーブル1[[#This Row],[Name]])," ","-"),".","-"),"&","-"),"_","-"),"・","-"),"=","-"),"--","-"),"--","-") -> kasane-teddo | C20: 重音テッド | D20: かさね てっど | E20: Kasane Teddo | F20: https://kasaneteto.jp | G20: #重音テッド | H20: キメラ | I20: バーチャル | K20: イヤーユニット | N20: 済 | O20: =テーブル1[[#This Row],[リンク]]&テーブル1[[#This Row],[描画状況]] -> https://kasaneteto.jp済 | P20: =1-(COUNTIF(O:O,_xlfn.TEXTJOIN(",",TRUE,テーブル1[[#This Row],[リンク]],テーブル1[[#This Row],[描画状況]]))/COUNTIF(F:F,テーブル1[[#This Row],[リンク]])) -> 1 | Q20: =IFERROR(IF(テーブル1[[#This Row],[描画状況]]="",RAND()+(テーブル1[[#This Row],[列2]]*100),""),RAND()) | R20: 済 | S20: =IF(AND(テーブル1[[#This Row],[描画状況]]="済",テーブル1[[#This Row],[投稿状況]]=""),RAND(),"") | T20: ="|&image("&テーブル1[[#This Row],[画像]]&".png,width=100,height=100)" -> |&image(kasane-teddo.png,width=100,height=100) | U20: ="|MIDDLE:​"&テーブル1[[#This Row],[名前]] -> |MIDDLE:​重音テッド | V20: ="|MIDDLE:​"&テーブル1[[#This Row],[なまえ]] -> |MIDDLE:​かさね てっど | W20: ="|MIDDLE:​"&テーブル1[[#This Row],[Name]] -> |MIDDLE:​Kasane Teddo | X20: ="|MIDDLE:​&link(配布所はこちら){​"&テーブル1[[#This Row],[リンク]]&"}|" -> |MIDDLE:​&link(配布所はこちら){​https://kasaneteto.jp}|
A21: 20 | B21: =SUBSTITUTE(SUBSTITUTE(SUBSTITUTE(SUBSTITUTE(SUBSTITUTE(SUBSTITUTE(SUBSTITUTE(SUBSTITUTE(LOWER(テーブル1[[#This Row],[Name]])," ","-"),".","-"),"&","-"),"_","-"),"・","-"),"=","-"),"--","-"),"--","-") -> kasane-teto | C21: 重音テト | D21: かさね てと | E21: Kasane Teto | F21: https://kasaneteto.jp | G21: #重音テト | H21: キメラ | I21: バーチャル | N21: 済 | O21: =テーブル1[[#This Row],[リンク]]&テーブル1[[#This Row],[描画状況]] -> https://kasaneteto.jp済 | P21: =1-(COUNTIF(O:O,_xlfn.TEXTJOIN(",",TRUE,テーブル1[[#This Row],[リンク]],テーブル1[[#This Row],[描画状況]]))/COUNTIF(F:F,テーブル1[[#This Row],[リンク]])) -> 1 | Q21: =IFERROR(IF(テーブル1[[#This Row],[描画状況]]="",RAND()+(テーブル1[[#This Row],[列2]]*100),""),RAND()) | R21: 済 | S21: =IF(AND(テーブル1[[#This Row],[描画状況]]="済",テーブル1[[#This Row],[投稿状況]]=""),RAND(),"") | T21: ="|&image("&テーブル1[[#This Row],[画像]]&".png,width=100,height=100)" -> |&image(kasane-teto.png,width=100,height=100) | U21: ="|MIDDLE:​"&テーブル1[[#This Row],[名前]] -> |MIDDLE:​重音テト | V21: ="|MIDDLE:​"&テーブル1[[#This Row],[なまえ]] -> |MIDDLE:​かさね てと | W21: ="|MIDDLE:​"&テーブル1[[#This Row],[Name]] -> |MIDDLE:​Kasane Teto | X21: ="|MIDDLE:​&link(配布所はこちら){​"&テーブル1[[#This Row],[リンク]]&"}|" -> |MIDDLE:​&link(配布所はこちら){​https://kasaneteto.jp}|
A22: 21 | B22: =SUBSTITUTE(SUBSTITUTE(SUBSTITUTE(SUBSTITUTE(SUBSTITUTE(SUBSTITUTE(SUBSTITUTE(SUBSTITUTE(LOWER(テーブル1[[#This Row],[Name]])," ","-"),".","-"),"&","-"),"_","-"),"・","-"),"=","-"),"--","-"),"--","-") -> kasumi-ua | C22: 化炭ウア | D22: かすみ うあ | E22: Kasumi Ua | F22: https://bowlroll.net/user/980255 | G22: #歌う雨やどり | H22: 女性 | I22: 堕天使 | L22: 両目隠れ|羽 | M22: 〇 / 不要 | N22: 済 | O22: =テーブル1[[#This Row],[リンク]]&テーブル1[[#This Row],[描画状況]] -> https://bowlroll.net/user/980255済 | P22: =1-(COUNTIF(O:O,_xlfn.TEXTJOIN(",",TRUE,テーブル1[[#This Row],[リンク]],テーブル1[[#This Row],[描画状況]]))/COUNTIF(F:F,テーブル1[[#This Row],[リンク]])) -> 1 | Q22: =IFERROR(IF(テーブル1[[#This Row],[描画状況]]="",RAND()+(テーブル1[[#This Row],[列2]]*100),""),RAND()) | R22: 済 | S22: =IF(AND(テーブル1[[#This Row],[描画状況]]="済",テーブル1[[#This Row],[投稿状況]]=""),RAND(),"") | T22: ="|&image("&テーブル1[[#This Row],[画像]]&".png,width=100,height=100)" -> |&image(kasumi-ua.png,width=100,height=100) | U22: ="|MIDDLE:​"&テーブル1[[#This Row],[名前]] -> |MIDDLE:​化炭ウア | V22: ="|MIDDLE:​"&テーブル1[[#This Row],[なまえ]] -> |MIDDLE:​かすみ うあ | W22: ="|MIDDLE:​"&テーブル1[[#This Row],[Name]] -> |MIDDLE:​Kasumi Ua | X22: ="|MIDDLE:​&link(配布所はこちら){​"&テーブル1[[#This Row],[リンク]]&"}|" -> |MIDDLE:​&link(配布所はこちら){​https://bowlroll.net/user/980255}|
A23: 22 | B23: =SUBSTITUTE(SUBSTITUTE(SUBSTITUTE(SUBSTITUTE(SUBSTITUTE(SUBSTITUTE(SUBSTITUTE(SUBSTITUTE(LOWER(テーブル1[[#This Row],[Name]])," ","-"),".","-"),"&","-"),"_","-"),"・","-"),"=","-"),"--","-"),"--","-") -> kazehiki | C23: カゼヒキ | D23: かぜひき | E23: Kazehiki | F23: https://kurukuru2suuzi.wixsite.com/kuzutokaze | G23: #くずかぜ | N23: 済 | O23: =テーブル1[[#This Row],[リンク]]&テーブル1[[#This Row],[描画状況]] -> https://kurukuru2suuzi.wixsite.com/kuzutokaze済 | P23: =1-(COUNTIF(O:O,_xlfn.TEXTJOIN(",",TRUE,テーブル1[[#This Row],[リンク]],テーブル1[[#This Row],[描画状況]]))/COUNTIF(F:F,テーブル1[[#This Row],[リンク]])) -> 1 | Q23: =IFERROR(IF(テーブル1[[#This Row],[描画状況]]="",RAND()+(テーブル1[[#This Row],[列2]]*100),""),RAND()) | R23: 済 | S23: =IF(AND(テーブル1[[#This Row],[描画状況]]="済",テーブル1[[#This Row],[投稿状況]]=""),RAND(),"") | T23: ="|&image("&テーブル1[[#This Row],[画像]]&".png,width=100,height=100)" -> |&image(kazehiki.png,width=100,height=100) | U23: ="|MIDDLE:​"&テーブル1[[#This Row],[名前]] -> |MIDDLE:​カゼヒキ | V23: ="|MIDDLE:​"&テーブル1[[#This Row],[なまえ]] -> |MIDDLE:​かぜひき | W23: ="|MIDDLE:​"&テーブル1[[#This Row],[Name]] -> |MIDDLE:​Kazehiki | X23: ="|MIDDLE:​&link(配布所はこちら){​"&テーブル1[[#This Row],[リンク]]&"}|" -> |MIDDLE:​&link(配布所はこちら){​https://kurukuru2suuzi.wixsite.com/kuzutokaze}|
A24: 23 | B24: =SUBSTITUTE(SUBSTITUTE(SUBSTITUTE(SUBSTITUTE(SUBSTITUTE(SUBSTITUTE(SUBSTITUTE(SUBSTITUTE(LOWER(テーブル1[[#This Row],[Name]])," ","-"),".","-"),"&","-"),"_","-"),"・","-"),"=","-"),"--","-"),"--","-") -> katabami | C24: カタバミ | D24: かたばみ | E24: Katabami | F24: https://seirentoybox.jimdofree.com | G24: #セレソー作 | H24: 不明 | I24: 人間|双子 | K24: 眼鏡 | M24: 〇 / 不要 | N24: 済 | O24: =テーブル1[[#This Row],[リンク]]&テーブル1[[#This Row],[描画状況]] -> https://seirentoybox.jimdofree.com済 | P24: =1-(COUNTIF(O:O,_xlfn.TEXTJOIN(",",TRUE,テーブル1[[#This Row],[リンク]],テーブル1[[#This Row],[描画状況]]))/COUNTIF(F:F,テーブル1[[#This Row],[リンク]])) -> 1 | Q24: =IFERROR(IF(テーブル1[[#This Row],[描画状況]]="",RAND()+(テーブル1[[#This Row],[列2]]*100),""),RAND()) | R24: 済 | S24: =IF(AND(テーブル1[[#This Row],[描画状況]]="済",テーブル1[[#This Row],[投稿状況]]=""),RAND(),"") | T24: ="|&image("&テーブル1[[#This Row],[画像]]&".png,width=100,height=100)" -> |&image(katabami.png,width=100,height=100) | U24: ="|MIDDLE:​"&テーブル1[[#This Row],[名前]] -> |MIDDLE:​カタバミ | V24: ="|MIDDLE:​"&テーブル1[[#This Row],[なまえ]] -> |MIDDLE:​かたばみ | W24: ="|MIDDLE:​"&テーブル1[[#This Row],[Name]] -> |MIDDLE:​Katabami | X24: ="|MIDDLE:​&link(配布所はこちら){​"&テーブル1[[#This Row],[リンク]]&"}|" -> |MIDDLE:​&link(配布所はこちら){​https://seirentoybox.jimdofree.com}|
A25: 24 | B25: =SUBSTITUTE(SUBSTITUTE(SUBSTITUTE(SUBSTITUTE(SUBSTITUTE(SUBSTITUTE(SUBSTITUTE(SUBSTITUTE(LOWER(テーブル1[[#This Row],[Name]])," ","-"),".","-"),"&","-"),"_","-"),"・","-"),"=","-"),"--","-"),"--","-") -> katabanhumei | C25: 型番不明 | D25: かたばんふめい | E25: Katabanhumei | F25: https://moqujc.wixsite.com/mqtop | G25: #MQAW | N25: 済 | O25: =テーブル1[[#This Row],[リンク]]&テーブル1[[#This Row],[描画状況]] -> https://moqujc.wixsite.com/mqtop済 | P25: =1-(COUNTIF(O:O,_xlfn.TEXTJOIN(",",TRUE,テーブル1[[#This Row],[リンク]],テーブル1[[#This Row],[描画状況]]))/COUNTIF(F:F,テーブル1[[#This Row],[リンク]])) -> 1 | Q25: =IFERROR(IF(テーブル1[[#This Row],[描画状況]]="",RAND()+(テーブル1[[#This Row],[列2]]*100),""),RAND()) | R25: 済 | S25: =IF(AND(テーブル1[[#This Row],[描画状況]]="済",テーブル1[[#This Row],[投稿状況]]=""),RAND(),"") | T25: ="|&image("&テーブル1[[#This Row],[画像]]&".png,width=100,height=100)" -> |&image(katabanhumei.png,width=100,height=100) | U25: ="|MIDDLE:​"&テーブル1[[#This Row],[名前]] -> |MIDDLE:​型番不明 | V25: ="|MIDDLE:​"&テーブル1[[#This Row],[なまえ]] -> |MIDDLE:​かたばんふめい | W25: ="|MIDDLE:​"&テーブル1[[#This Row],[Name]] -> |MIDDLE:​Katabanhumei | X25: ="|MIDDLE:​&link(配布所はこちら){​"&テーブル1[[#This Row],[リンク]]&"}|" -> |MIDDLE:​&link(配布所はこちら){​https://moqujc.wixsite.com/mqtop}|
A26: 25 | B26: =SUBSTITUTE(SUBSTITUTE(SUBSTITUTE(SUBSTITUTE(SUBSTITUTE(SUBSTITUTE(SUBSTITUTE(SUBSTITUTE(LOWER(テーブル1[[#This Row],[Name]])," ","-"),".","-"),"&","-"),"_","-"),"・","-"),"=","-"),"--","-"),"--","-") -> kanade-shia | C26: 花撫シア | D26: かなで しあ | E26: Kanade Shia | F26: https://itsuriutau.wixsite.com/kanadeshia | G26: #花撫シア | N26: 済 | O26: =テーブル1[[#This Row],[リンク]]&テーブル1[[#This Row],[描画状況]] -> https://itsuriutau.wixsite.com/kanadeshia済 | P26: =1-(COUNTIF(O:O,_xlfn.TEXTJOIN(",",TRUE,テーブル1[[#This Row],[リンク]],テーブル1[[#This Row],[描画状況]]))/COUNTIF(F:F,テーブル1[[#This Row],[リンク]])) -> 1 | Q26: =IFERROR(IF(テーブル1[[#This Row],[描画状況]]="",RAND()+(テーブル1[[#This Row],[列2]]*100),""),RAND()) | R26: 済 | S26: =IF(AND(テーブル1[[#This Row],[描画状況]]="済",テーブル1[[#This Row],[投稿状況]]=""),RAND(),"") | T26: ="|&image("&テーブル1[[#This Row],[画像]]&".png,width=100,height=100)" -> |&image(kanade-shia.png,width=100,height=100) | U26: ="|MIDDLE:​"&テーブル1[[#This Row],[名前]] -> |MIDDLE:​花撫シア | V26: ="|MIDDLE:​"&テーブル1[[#This Row],[なまえ]] -> |MIDDLE:​かなで しあ | W26: ="|MIDDLE:​"&テーブル1[[#This Row],[Name]] -> |MIDDLE:​Kanade Shia | X26: ="|MIDDLE:​&link(配布所はこちら){​"&テーブル1[[#This Row],[リンク]]&"}|" -> |MIDDLE:​&link(配布所はこちら){​https://itsuriutau.wixsite.com/kanadeshia}|
A27: 26 | B27: =SUBSTITUTE(SUBSTITUTE(SUBSTITUTE(SUBSTITUTE(SUBSTITUTE(SUBSTITUTE(SUBSTITUTE(SUBSTITUTE(LOWER(テーブル1[[#This Row],[Name]])," ","-"),".","-"),"&","-"),"_","-"),"・","-"),"=","-"),"--","-"),"--","-") -> kanade-shion | C27: 花撫シオン | D27: かなで しおん | E27: Kanade Shion | F27: https://itsuriutau.wixsite.com/kanadeshia | G27: #花撫シオン | N27: 済 | O27: =テーブル1[[#This Row],[リンク]]&テーブル1[[#This Row],[描画状況]] -> https://itsuriutau.wixsite.com/kanadeshia済 | P27: =1-(COUNTIF(O:O,_xlfn.TEXTJOIN(",",TRUE,テーブル1[[#This Row],[リンク]],テーブル1[[#This Row],[描画状況]]))/COUNTIF(F:F,テーブル1[[#This Row],[リンク]])) -> 1 | Q27: =IFERROR(IF(テーブル1[[#This Row],[描画状況]]="",RAND()+(テーブル1[[#This Row],[列2]]*100),""),RAND()) | R27: 済 | S27: =IF(AND(テーブル1[[#This Row],[描画状況]]="済",テーブル1[[#This Row],[投稿状況]]=""),RAND(),"") | T27: ="|&image("&テーブル1[[#This Row],[画像]]&".png,width=100,height=100)" -> |&image(kanade-shion.png,width=100,height=100) | U27: ="|MIDDLE:​"&テーブル1[[#This Row],[名前]] -> |MIDDLE:​花撫シオン | V27: ="|MIDDLE:​"&テーブル1[[#This Row],[なまえ]] -> |MIDDLE:​かなで しおん | W27: ="|MIDDLE:​"&テーブル1[[#This Row],[Name]] -> |MIDDLE:​Kanade Shion | X27: ="|MIDDLE:​&link(配布所はこちら){​"&テーブル1[[#This Row],[リンク]]&"}|" -> |MIDDLE:​&link(配布所はこちら){​https://itsuriutau.wixsite.com/kanadeshia}|
A28: 27 | B28: =SUBSTITUTE(SUBSTITUTE(SUBSTITUTE(SUBSTITUTE(SUBSTITUTE(SUBSTITUTE(SUBSTITUTE(SUBSTITUTE(LOWER(テーブル1[[#This Row],[Name]])," ","-"),".","-"),"&","-"),"_","-"),"・","-"),"=","-"),"--","-"),"--","-") -> kanari-niito | C28: 歌為にーと | D28: かなり にーと | E28: Kanari Niito | F28: https://bowlroll.net/user/852117/files | G28: #きのみあーと | M28: 〇 / 不要 | N28: 済 | O28: =テーブル1[[#This Row],[リンク]]&テーブル1[[#This Row],[描画状況]] -> https://bowlroll.net/user/852117/files済 | P28: =1-(COUNTIF(O:O,_xlfn.TEXTJOIN(",",TRUE,テーブル1[[#This Row],[リンク]],テーブル1[[#This Row],[描画状況]]))/COUNTIF(F:F,テーブル1[[#This Row],[リンク]])) -> 1 | Q28: =IFERROR(IF(テーブル1[[#This Row],[描画状況]]="",RAND()+(テーブル1[[#This Row],[列2]]*100),""),RAND()) | R28: 済 | S28: =IF(AND(テーブル1[[#This Row],[描画状況]]="済",テーブル1[[#This Row],[投稿状況]]=""),RAND(),"") | T28: ="|&image("&テーブル1[[#This Row],[画像]]&".png,width=100,height=100)" -> |&image(kanari-niito.png,width=100,height=100) | U28: ="|MIDDLE:​"&テーブル1[[#This Row],[名前]] -> |MIDDLE:​歌為にーと | V28: ="|MIDDLE:​"&テーブル1[[#This Row],[なまえ]] -> |MIDDLE:​かなり にーと | W28: ="|MIDDLE:​"&テーブル1[[#This Row],[Name]] -> |MIDDLE:​Kanari Niito | X28: ="|MIDDLE:​&link(配布所はこちら){​"&テーブル1[[#This Row],[リンク]]&"}|" -> |MIDDLE:​&link(配布所はこちら){​https://bowlroll.net/user/852117/files}|
A29: 28 | B29: =SUBSTITUTE(SUBSTITUTE(SUBSTITUTE(SUBSTITUTE(SUBSTITUTE(SUBSTITUTE(SUBSTITUTE(SUBSTITUTE(LOWER(テーブル1[[#This Row],[Name]])," ","-"),".","-"),"&","-"),"_","-"),"・","-"),"=","-"),"--","-"),"--","-") -> karane-kyoka | C29: 空音響歌 | D29: からね きょうか | E29: Karane Kyoka | F29: https://kaitoramma.chu.jp | G29: #空音絵巻 | N29: 済 | O29: =テーブル1[[#This Row],[リンク]]&テーブル1[[#This Row],[描画状況]] -> https://kaitoramma.chu.jp済 | P29: =1-(COUNTIF(O:O,_xlfn.TEXTJOIN(",",TRUE,テーブル1[[#This Row],[リンク]],テーブル1[[#This Row],[描画状況]]))/COUNTIF(F:F,テーブル1[[#This Row],[リンク]])) -> 1 | Q29: =IFERROR(IF(テーブル1[[#This Row],[描画状況]]="",RAND()+(テーブル1[[#This Row],[列2]]*100),""),RAND()) | R29: 済 | S29: =IF(AND(テーブル1[[#This Row],[描画状況]]="済",テーブル1[[#This Row],[投稿状況]]=""),RAND(),"") | T29: ="|&image("&テーブル1[[#This Row],[画像]]&".png,width=100,height=100)" -> |&image(karane-kyoka.png,width=100,height=100) | U29: ="|MIDDLE:​"&テーブル1[[#This Row],[名前]] -> |MIDDLE:​空音響歌 | V29: ="|MIDDLE:​"&テーブル1[[#This Row],[なまえ]] -> |MIDDLE:​からね きょうか | W29: ="|MIDDLE:​"&テーブル1[[#This Row],[Name]] -> |MIDDLE:​Karane Kyoka | X29: ="|MIDDLE:​&link(配布所はこちら){​"&テーブル1[[#This Row],[リンク]]&"}|" -> |MIDDLE:​&link(配布所はこちら){​https://kaitoramma.chu.jp}|
A30: 29 | B30: =SUBSTITUTE(SUBSTITUTE(SUBSTITUTE(SUBSTITUTE(SUBSTITUTE(SUBSTITUTE(SUBSTITUTE(SUBSTITUTE(LOWER(テーブル1[[#This Row],[Name]])," ","-"),".","-"),"&","-"),"_","-"),"・","-"),"=","-"),"--","-"),"--","-") -> karane-hibiki | C30: 空音ヒビキ | D30: からね ひびき | E30: Karane Hibiki | F30: https://kaitoramma.chu.jp | G30: #空音絵巻 | N30: 済 | O30: =テーブル1[[#This Row],[リンク]]&テーブル1[[#This Row],[描画状況]] -> https://kaitoramma.chu.jp済 | P30: =1-(COUNTIF(O:O,_xlfn.TEXTJOIN(",",TRUE,テーブル1[[#This Row],[リンク]],テーブル1[[#This Row],[描画状況]]))/COUNTIF(F:F,テーブル1[[#This Row],[リンク]])) -> 1 | Q30: =IFERROR(IF(テーブル1[[#This Row],[描画状況]]="",RAND()+(テーブル1[[#This Row],[列2]]*100),""),RAND()) | R30: 済 | S30: =IF(AND(テーブル1[[#This Row],[描画状況]]="済",テーブル1[[#This Row],[投稿状況]]=""),RAND(),"") | T30: ="|&image("&テーブル1[[#This Row],[画像]]&".png,width=100,height=100)" -> |&image(karane-hibiki.png,width=100,height=100) | U30: ="|MIDDLE:​"&テーブル1[[#This Row],[名前]] -> |MIDDLE:​空音ヒビキ | V30: ="|MIDDLE:​"&テーブル1[[#This Row],[なまえ]] -> |MIDDLE:​からね ひびき | W30: ="|MIDDLE:​"&テーブル1[[#This Row],[Name]] -> |MIDDLE:​Karane Hibiki | X30: ="|MIDDLE:​&link(配布所はこちら){​"&テーブル1[[#This Row],[リンク]]&"}|" -> |MIDDLE:​&link(配布所はこちら){​https://kaitoramma.chu.jp}|
A31: 30 | B31: =SUBSTITUTE(SUBSTITUTE(SUBSTITUTE(SUBSTITUTE(SUBSTITUTE(SUBSTITUTE(SUBSTITUTE(SUBSTITUTE(LOWER(テーブル1[[#This Row],[Name]])," ","-"),".","-"),"&","-"),"_","-"),"・","-"),"=","-"),"--","-"),"--","-") -> kiyenn | C31: キエン | D31: きえん | E31: Kiyenn | F31: https://utaunanaproplus.wixsite.com/of-web | G31: #TNPGateway | N31: 済 | O31: =テーブル1[[#This Row],[リンク]]&テーブル1[[#This Row],[描画状況]] -> https://utaunanaproplus.wixsite.com/of-web済 | P31: =1-(COUNTIF(O:O,_xlfn.TEXTJOIN(",",TRUE,テーブル1[[#This Row],[リンク]],テーブル1[[#This Row],[描画状況]]))/COUNTIF(F:F,テーブル1[[#This Row],[リンク]])) -> 1 | Q31: =IFERROR(IF(テーブル1[[#This Row],[描画状況]]="",RAND()+(テーブル1[[#This Row],[列2]]*100),""),RAND()) | R31: 済 | S31: =IF(AND(テーブル1[[#This Row],[描画状況]]="済",テーブル1[[#This Row],[投稿状況]]=""),RAND(),"") | T31: ="|&image("&テーブル1[[#This Row],[画像]]&".png,width=100,height=100)" -> |&image(kiyenn.png,width=100,height=100) | U31: ="|MIDDLE:​"&テーブル1[[#This Row],[名前]] -> |MIDDLE:​キエン | V31: ="|MIDDLE:​"&テーブル1[[#This Row],[なまえ]] -> |MIDDLE:​きえん | W31: ="|MIDDLE:​"&テーブル1[[#This Row],[Name]] -> |MIDDLE:​Kiyenn | X31: ="|MIDDLE:​&link(配布所はこちら){​"&テーブル1[[#This Row],[リンク]]&"}|" -> |MIDDLE:​&link(配布所はこちら){​https://utaunanaproplus.wixsite.com/of-web}|
A32: 31 | B32: =SUBSTITUTE(SUBSTITUTE(SUBSTITUTE(SUBSTITUTE(SUBSTITUTE(SUBSTITUTE(SUBSTITUTE(SUBSTITUTE(LOWER(テーブル1[[#This Row],[Name]])," ","-"),".","-"),"&","-"),"_","-"),"・","-"),"=","-"),"--","-"),"--","-") -> kigeki-warota | C32: 喜檄わろた | D32: きげき わろた | E32: Kigeki Warota | F32: https://seirentoybox.jimdofree.com | G32: #セレソー作 | H32: 女性 | I32: 妖精|双子 | J32: サーカス団員 | K32: リボン | L32: ギザ歯 | M32: 〇 / 不要 | N32: 済 | O32: =テーブル1[[#This Row],[リンク]]&テーブル1[[#This Row],[描画状況]] -> https://seirentoybox.jimdofree.com済 | P32: =1-(COUNTIF(O:O,_xlfn.TEXTJOIN(",",TRUE,テーブル1[[#This Row],[リンク]],テーブル1[[#This Row],[描画状況]]))/COUNTIF(F:F,テーブル1[[#This Row],[リンク]])) -> 1 | Q32: =IFERROR(IF(テーブル1[[#This Row],[描画状況]]="",RAND()+(テーブル1[[#This Row],[列2]]*100),""),RAND()) | R32: 済 | S32: =IF(AND(テーブル1[[#This Row],[描画状況]]="済",テーブル1[[#This Row],[投稿状況]]=""),RAND(),"") | T32: ="|&image("&テーブル1[[#This Row],[画像]]&".png,width=100,height=100)" -> |&image(kigeki-warota.png,width=100,height=100) | U32: ="|MIDDLE:​"&テーブル1[[#This Row],[名前]] -> |MIDDLE:​喜檄わろた | V32: ="|MIDDLE:​"&テーブル1[[#This Row],[なまえ]] -> |MIDDLE:​きげき わろた | W32: ="|MIDDLE:​"&テーブル1[[#This Row],[Name]] -> |MIDDLE:​Kigeki Warota | X32: ="|MIDDLE:​&link(配布所はこちら){​"&テーブル1[[#This Row],[リンク]]&"}|" -> |MIDDLE:​&link(配布所はこちら){​https://seirentoybox.jimdofree.com}|
A33: 32 | B33: =SUBSTITUTE(SUBSTITUTE(SUBSTITUTE(SUBSTITUTE(SUBSTITUTE(SUBSTITUTE(SUBSTITUTE(SUBSTITUTE(LOWER(テーブル1[[#This Row],[Name]])," ","-"),".","-"),"&","-"),"_","-"),"・","-"),"=","-"),"--","-"),"--","-") -> kizuboshi-sora | C33: 創星宙 | D33: きずぼし そら | E33: Kizuboshi Sora | F33: https://nyaruru.wixsite.com/s-p-w | G33: #創星宙 | N33: 済 | O33: =テーブル1[[#This Row],[リンク]]&テーブル1[[#This Row],[描画状況]] -> https://nyaruru.wixsite.com/s-p-w済 | P33: =1-(COUNTIF(O:O,_xlfn.TEXTJOIN(",",TRUE,テーブル1[[#This Row],[リンク]],テーブル1[[#This Row],[描画状況]]))/COUNTIF(F:F,テーブル1[[#This Row],[リンク]])) -> 1 | Q33: =IFERROR(IF(テーブル1[[#This Row],[描画状況]]="",RAND()+(テーブル1[[#This Row],[列2]]*100),""),RAND()) | R33: 済 | S33: =IF(AND(テーブル1[[#This Row],[描画状況]]="済",テーブル1[[#This Row],[投稿状況]]=""),RAND(),"") | T33: ="|&image("&テーブル1[[#This Row],[画像]]&".png,width=100,height=100)" -> |&image(kizuboshi-sora.png,width=100,height=100) | U33: ="|MIDDLE:​"&テーブル1[[#This Row],[名前]] -> |MIDDLE:​創星宙 | V33: ="|MIDDLE:​"&テーブル1[[#This Row],[なまえ]] -> |MIDDLE:​きずぼし そら | W33: ="|MIDDLE:​"&テーブル1[[#This Row],[Name]] -> |MIDDLE:​Kizuboshi Sora | X33: ="|MIDDLE:​&link(配布所はこちら){​"&テーブル1[[#This Row],[リンク]]&"}|" -> |MIDDLE:​&link(配布所はこちら){​https://nyaruru.wixsite.com/s-p-w}|
A34: 33 | B34: =SUBSTITUTE(SUBSTITUTE(SUBSTITUTE(SUBSTITUTE(SUBSTITUTE(SUBSTITUTE(SUBSTITUTE(SUBSTITUTE(LOWER(テーブル1[[#This Row],[Name]])," ","-"),".","-"),"&","-"),"_","-"),"・","-"),"=","-"),"--","-"),"--","-") -> kine-kine | C34: キ音キネ | D34: きね きね | E34: Kine kine | F34: https://bowlroll.net/user/852117/files | G34: #きのみあーと | M34: 〇 / 不要 | N34: 済 | O34: =テーブル1[[#This Row],[リンク]]&テーブル1[[#This Row],[描画状況]] -> https://bowlroll.net/user/852117/files済 | P34: =1-(COUNTIF(O:O,_xlfn.TEXTJOIN(",",TRUE,テーブル1[[#This Row],[リンク]],テーブル1[[#This Row],[描画状況]]))/COUNTIF(F:F,テーブル1[[#This Row],[リンク]])) -> 1 | Q34: =IFERROR(IF(テーブル1[[#This Row],[描画状況]]="",RAND()+(テーブル1[[#This Row],[列2]]*100),""),RAND()) | R34: 済 | S34: =IF(AND(テーブル1[[#This Row],[描画状況]]="済",テーブル1[[#This Row],[投稿状況]]=""),RAND(),"") | T34: ="|&image("&テーブル1[[#This Row],[画像]]&".png,width=100,height=100)" -> |&image(kine-kine.png,width=100,height=100) | U34: ="|MIDDLE:​"&テーブル1[[#This Row],[名前]] -> |MIDDLE:​キ音キネ | V34: ="|MIDDLE:​"&テーブル1[[#This Row],[なまえ]] -> |MIDDLE:​きね きね | W34: ="|MIDDLE:​"&テーブル1[[#This Row],[Name]] -> |MIDDLE:​Kine kine | X34: ="|MIDDLE:​&link(配布所はこちら){​"&テーブル1[[#This Row],[リンク]]&"}|" -> |MIDDLE:​&link(配布所はこちら){​https://bowlroll.net/user/852117/files}|
A35: 34 | B35: =SUBSTITUTE(SUBSTITUTE(SUBSTITUTE(SUBSTITUTE(SUBSTITUTE(SUBSTITUTE(SUBSTITUTE(SUBSTITUTE(LOWER(テーブル1[[#This Row],[Name]])," ","-"),".","-"),"&","-"),"_","-"),"・","-"),"=","-"),"--","-"),"--","-") -> kyomachi-morte | C35: 凶街モルテ | D35: きょうまち もるて | E35: Kyomachi Morte | F35: https://utaunanaproplus.wixsite.com/of-web | G35: #TNPGateway | N35: 済 | O35: =テーブル1[[#This Row],[リンク]]&テーブル1[[#This Row],[描画状況]] -> https://utaunanaproplus.wixsite.com/of-web済 | P35: =1-(COUNTIF(O:O,_xlfn.TEXTJOIN(",",TRUE,テーブル1[[#This Row],[リンク]],テーブル1[[#This Row],[描画状況]]))/COUNTIF(F:F,テーブル1[[#This Row],[リンク]])) -> 1 | Q35: =IFERROR(IF(テーブル1[[#This Row],[描画状況]]="",RAND()+(テーブル1[[#This Row],[列2]]*100),""),RAND()) | R35: 済 | S35: =IF(AND(テーブル1[[#This Row],[描画状況]]="済",テーブル1[[#This Row],[投稿状況]]=""),RAND(),"") | T35: ="|&image("&テーブル1[[#This Row],[画像]]&".png,width=100,height=100)" -> |&image(kyomachi-morte.png,width=100,height=100) | U35: ="|MIDDLE:​"&テーブル1[[#This Row],[名前]] -> |MIDDLE:​凶街モルテ | V35: ="|MIDDLE:​"&テーブル1[[#This Row],[なまえ]] -> |MIDDLE:​きょうまち もるて | W35: ="|MIDDLE:​"&テーブル1[[#This Row],[Name]] -> |MIDDLE:​Kyomachi Morte | X35: ="|MIDDLE:​&link(配布所はこちら){​"&テーブル1[[#This Row],[リンク]]&"}|" -> |MIDDLE:​&link(配布所はこちら){​https://utaunanaproplus.wixsite.com/of-web}|
A36: 35 | B36: =SUBSTITUTE(SUBSTITUTE(SUBSTITUTE(SUBSTITUTE(SUBSTITUTE(SUBSTITUTE(SUBSTITUTE(SUBSTITUTE(LOWER(テーブル1[[#This Row],[Name]])," ","-"),".","-"),"&","-"),"_","-"),"・","-"),"=","-"),"--","-"),"--","-") -> kiraboshi-waku | C36: 輝星惑 | D36: きらぼし わく | E36: Kiraboshi Waku | F36: https://nyaruru.wixsite.com/s-p-w | G36: #輝星惑 | N36: 済 | O36: =テーブル1[[#This Row],[リンク]]&テーブル1[[#This Row],[描画状況]] -> https://nyaruru.wixsite.com/s-p-w済 | P36: =1-(COUNTIF(O:O,_xlfn.TEXTJOIN(",",TRUE,テーブル1[[#This Row],[リンク]],テーブル1[[#This Row],[描画状況]]))/COUNTIF(F:F,テーブル1[[#This Row],[リンク]])) -> 1 | Q36: =IFERROR(IF(テーブル1[[#This Row],[描画状況]]="",RAND()+(テーブル1[[#This Row],[列2]]*100),""),RAND()) | R36: 済 | S36: =IF(AND(テーブル1[[#This Row],[描画状況]]="済",テーブル1[[#This Row],[投稿状況]]=""),RAND(),"") | T36: ="|&image("&テーブル1[[#This Row],[画像]]&".png,width=100,height=100)" -> |&image(kiraboshi-waku.png,width=100,height=100) | U36: ="|MIDDLE:​"&テーブル1[[#This Row],[名前]] -> |MIDDLE:​輝星惑 | V36: ="|MIDDLE:​"&テーブル1[[#This Row],[なまえ]] -> |MIDDLE:​きらぼし わく | W36: ="|MIDDLE:​"&テーブル1[[#This Row],[Name]] -> |MIDDLE:​Kiraboshi Waku | X36: ="|MIDDLE:​&link(配布所はこちら){​"&テーブル1[[#This Row],[リンク]]&"}|" -> |MIDDLE:​&link(配布所はこちら){​https://nyaruru.wixsite.com/s-p-w}|
A37: 36 | B37: =SUBSTITUTE(SUBSTITUTE(SUBSTITUTE(SUBSTITUTE(SUBSTITUTE(SUBSTITUTE(SUBSTITUTE(SUBSTITUTE(LOWER(テーブル1[[#This Row],[Name]])," ","-"),".","-"),"&","-"),"_","-"),"・","-"),"=","-"),"--","-"),"--","-") -> kuzyaku-eren | C37: 玖婥えれん | D37: くじゃく えれん | E37: Kuzyaku Eren | F37: https://hznonoka.wixsite.com/utau | G37: #あひのん #玖婥えれん | M37: 〇 / 不要 | N37: 済 | O37: =テーブル1[[#This Row],[リンク]]&テーブル1[[#This Row],[描画状況]] -> https://hznonoka.wixsite.com/utau済 | P37: =1-(COUNTIF(O:O,_xlfn.TEXTJOIN(",",TRUE,テーブル1[[#This Row],[リンク]],テーブル1[[#This Row],[描画状況]]))/COUNTIF(F:F,テーブル1[[#This Row],[リンク]])) -> 1 | Q37: =IFERROR(IF(テーブル1[[#This Row],[描画状況]]="",RAND()+(テーブル1[[#This Row],[列2]]*100),""),RAND()) | R37: 済 | S37: =IF(AND(テーブル1[[#This Row],[描画状況]]="済",テーブル1[[#This Row],[投稿状況]]=""),RAND(),"") | T37: ="|&image("&テーブル1[[#This Row],[画像]]&".png,width=100,height=100)" -> |&image(kuzyaku-eren.png,width=100,height=100) | U37: ="|MIDDLE:​"&テーブル1[[#This Row],[名前]] -> |MIDDLE:​玖婥えれん | V37: ="|MIDDLE:​"&テーブル1[[#This Row],[なまえ]] -> |MIDDLE:​くじゃく えれん | W37: ="|MIDDLE:​"&テーブル1[[#This Row],[Name]] -> |MIDDLE:​Kuzyaku Eren | X37: ="|MIDDLE:​&link(配布所はこちら){​"&テーブル1[[#This Row],[リンク]]&"}|" -> |MIDDLE:​&link(配布所はこちら){​https://hznonoka.wixsite.com/utau}|
A38: 37 | B38: =SUBSTITUTE(SUBSTITUTE(SUBSTITUTE(SUBSTITUTE(SUBSTITUTE(SUBSTITUTE(SUBSTITUTE(SUBSTITUTE(LOWER(テーブル1[[#This Row],[Name]])," ","-"),".","-"),"&","-"),"_","-"),"・","-"),"=","-"),"--","-"),"--","-") -> kuchinashi-awo | C38: 口無アヲ | D38: くちなし あを | E38: Kuchinashi Awo | F38: https://nichikuniku1129063.wixsite.com/website-3 | G38: #Pietà_ | N38: 済 | O38: =テーブル1[[#This Row],[リンク]]&テーブル1[[#This Row],[描画状況]] -> https://nichikuniku1129063.wixsite.com/website-3済 | P38: =1-(COUNTIF(O:O,_xlfn.TEXTJOIN(",",TRUE,テーブル1[[#This Row],[リンク]],テーブル1[[#This Row],[描画状況]]))/COUNTIF(F:F,テーブル1[[#This Row],[リンク]])) -> 1 | Q38: =IFERROR(IF(テーブル1[[#This Row],[描画状況]]="",RAND()+(テーブル1[[#This Row],[列2]]*100),""),RAND()) | R38: 済 | S38: =IF(AND(テーブル1[[#This Row],[描画状況]]="済",テーブル1[[#This Row],[投稿状況]]=""),RAND(),"") | T38: ="|&image("&テーブル1[[#This Row],[画像]]&".png,width=100,height=100)" -> |&image(kuchinashi-awo.png,width=100,height=100) | U38: ="|MIDDLE:​"&テーブル1[[#This Row],[名前]] -> |MIDDLE:​口無アヲ | V38: ="|MIDDLE:​"&テーブル1[[#This Row],[なまえ]] -> |MIDDLE:​くちなし あを | W38: ="|MIDDLE:​"&テーブル1[[#This Row],[Name]] -> |MIDDLE:​Kuchinashi Awo | X38: ="|MIDDLE:​&link(配布所はこちら){​"&テーブル1[[#This Row],[リンク]]&"}|" -> |MIDDLE:​&link(配布所はこちら){​https://nichikuniku1129063.wixsite.com/website-3}|
A39: 38 | B39: =SUBSTITUTE(SUBSTITUTE(SUBSTITUTE(SUBSTITUTE(SUBSTITUTE(SUBSTITUTE(SUBSTITUTE(SUBSTITUTE(LOWER(テーブル1[[#This Row],[Name]])," ","-"),".","-"),"&","-"),"_","-"),"・","-"),"=","-"),"--","-"),"--","-") -> kurobousuku | C39: 黒昴宿 | D39: くろぼうすく | E39: Kurobousuku | F39: https://subarumusicstore.studio.site | G39: #赤黒快日 | N39: 済 | O39: =テーブル1[[#This Row],[リンク]]&テーブル1[[#This Row],[描画状況]] -> https://subarumusicstore.studio.site済 | P39: =1-(COUNTIF(O:O,_xlfn.TEXTJOIN(",",TRUE,テーブル1[[#This Row],[リンク]],テーブル1[[#This Row],[描画状況]]))/COUNTIF(F:F,テーブル1[[#This Row],[リンク]])) -> 1 | Q39: =IFERROR(IF(テーブル1[[#This Row],[描画状況]]="",RAND()+(テーブル1[[#This Row],[列2]]*100),""),RAND()) | R39: 済 | S39: =IF(AND(テーブル1[[#This Row],[描画状況]]="済",テーブル1[[#This Row],[投稿状況]]=""),RAND(),"") | T39: ="|&image("&テーブル1[[#This Row],[画像]]&".png,width=100,height=100)" -> |&image(kurobousuku.png,width=100,height=100) | U39: ="|MIDDLE:​"&テーブル1[[#This Row],[名前]] -> |MIDDLE:​黒昴宿 | V39: ="|MIDDLE:​"&テーブル1[[#This Row],[なまえ]] -> |MIDDLE:​くろぼうすく | W39: ="|MIDDLE:​"&テーブル1[[#This Row],[Name]] -> |MIDDLE:​Kurobousuku | X39: ="|MIDDLE:​&link(配布所はこちら){​"&テーブル1[[#This Row],[リンク]]&"}|" -> |MIDDLE:​&link(配布所はこちら){​https://subarumusicstore.studio.site}|
A40: 39 | B40: =SUBSTITUTE(SUBSTITUTE(SUBSTITUTE(SUBSTITUTE(SUBSTITUTE(SUBSTITUTE(SUBSTITUTE(SUBSTITUTE(LOWER(テーブル1[[#This Row],[Name]])," ","-"),".","-"),"&","-"),"_","-"),"・","-"),"=","-"),"--","-"),"--","-") -> kei | C40: 蛍(ケイ) | D40: けい | E40: Kei | F40: http://park2.wakwak.com/~mbox/vo/hk/hkfre.htm | G40: #蛍_UTAU | M40: 〇 / 必要 | N40: 済 | O40: =テーブル1[[#This Row],[リンク]]&テーブル1[[#This Row],[描画状況]] -> http://park2.wakwak.com/~mbox/vo/hk/hkfre.htm済 | P40: =1-(COUNTIF(O:O,_xlfn.TEXTJOIN(",",TRUE,テーブル1[[#This Row],[リンク]],テーブル1[[#This Row],[描画状況]]))/COUNTIF(F:F,テーブル1[[#This Row],[リンク]])) -> 1 | Q40: =IFERROR(IF(テーブル1[[#This Row],[描画状況]]="",RAND()+(テーブル1[[#This Row],[列2]]*100),""),RAND()) | R40: 済 | S40: =IF(AND(テーブル1[[#This Row],[描画状況]]="済",テーブル1[[#This Row],[投稿状況]]=""),RAND(),"") | T40: ="|&image("&テーブル1[[#This Row],[画像]]&".png,width=100,height=100)" -> |&image(kei.png,width=100,height=100) | U40: ="|MIDDLE:​"&テーブル1[[#This Row],[名前]] -> |MIDDLE:​蛍(ケイ) | V40: ="|MIDDLE:​"&テーブル1[[#This Row],[なまえ]] -> |MIDDLE:​けい | W40: ="|MIDDLE:​"&テーブル1[[#This Row],[Name]] -> |MIDDLE:​Kei | X40: ="|MIDDLE:​&link(配布所はこちら){​"&テーブル1[[#This Row],[リンク]]&"}|" -> |MIDDLE:​&link(配布所はこちら){​http://park2.wakwak.com/~mbox/vo/hk/hkfre.htm}|
...

Sheet ガチャ
B2: キャラクターガチャ
B4: 行番号 | C4: =MATCH(C5,キャラ情報!C:C,0) -> 337
B5: 名前 | C5: =INDEX(キャラ情報!C:Q,MATCH(MIN(キャラ情報!Q:Q),キャラ情報!Q:Q,0),1) -> 李音フヱル
B6: リンク | C6: =INDEX(キャラ情報!C:Q,MATCH(MIN(キャラ情報!Q:Q),キャラ情報!Q:Q,0),4) -> https://suukedayo.wixsite.com/shiawasefairu
B9: 投稿ガチャ
B11: 行番号 | C11: =MATCH(C12,キャラ情報!C:C,0) -> #N/A
B12: 名前 | C12: =INDEX(キャラ情報!C:S,MATCH(MIN(キャラ情報!S:S),キャラ情報!S:S,0),1) -> #N/A
B14: ■投稿文
B15: ＼＼UTAUアイコン追加！📣／／
B17: ="No."&MAX(キャラ情報!A:A)+1&"｜" -> No.233｜ | C17: =C12 -> #N/A
B18: =INDEX(キャラ情報!C:G,MATCH(C12,キャラ情報!C:C,0),5) -> #N/A
B20: まとめはこちら ↓
B21: 🔗https://nyaruru-02.github.io/UTAU-Character-Icon-Library

Sheet csv変換
A1: id | B1: name | C1: kana | D1: romaji | E1: icon | F1: url | G1: workTags | H1: gender | I1: 種族タグ | J1: 職業タグ | K1: 小物タグ | L1: ワンポイントタグ
A2: =テーブル1[[#This Row],[番号]] -> 1 | B2: =テーブル1[[#This Row],[名前]] -> 赤鐘芙蓉 | C2: =テーブル1[[#This Row],[なまえ]] -> あかがね ふよう | D2: =テーブル1[[#This Row],[Name]] -> Akagane Fuyo | E2: ="image/"&テーブル1[[#This Row],[画像]]&".png" -> image/akagane-fuyo.png | F2: =テーブル1[[#This Row],[リンク]] -> https://mitoristu.wixsite.com/kousaibako | G2: =SUBSTITUTE(テーブル1[[#This Row],[作品タグ]]," ","|") -> #虹彩箱 | H2: =テーブル1[[#This Row],[性別]]&"" -> 女性 | I2: =テーブル1[[#This Row],[種族タグ]]&"" -> 鬼 | J2: =テーブル1[[#This Row],[職業タグ]]&"" | K2: =テーブル1[[#This Row],[小物タグ]]&"" | L2: =テーブル1[[#This Row],[ワンポイントタグ]]&"" -> 尖耳
A3: =テーブル1[[#This Row],[番号]] -> 2 | B3: =テーブル1[[#This Row],[名前]] -> 東屋亭久一 | C3: =テーブル1[[#This Row],[なまえ]] -> あずまやてい きゅういち | D3: =テーブル1[[#This Row],[Name]] -> Azumayatei Kyuichi | E3: ="image/"&テーブル1[[#This Row],[画像]]&".png" -> image/azumayatei-kyuichi.png | F3: =テーブル1[[#This Row],[リンク]] -> https://lit.link/sereinrain | G3: =SUBSTITUTE(テーブル1[[#This Row],[作品タグ]]," ","|") -> #東屋でお茶でも | H3: =テーブル1[[#This Row],[性別]]&"" -> 男性 | I3: =テーブル1[[#This Row],[種族タグ]]&"" -> 人間 | J3: =テーブル1[[#This Row],[職業タグ]]&"" -> 学者 | K3: =テーブル1[[#This Row],[小物タグ]]&"" -> 眼鏡 | L3: =テーブル1[[#This Row],[ワンポイントタグ]]&"" -> インナーカラー|片目隠れ
A4: =テーブル1[[#This Row],[番号]] -> 3 | B4: =テーブル1[[#This Row],[名前]] -> アセテート | C4: =テーブル1[[#This Row],[なまえ]] -> あせてーと | D4: =テーブル1[[#This Row],[Name]] -> Acetate | E4: ="image/"&テーブル1[[#This Row],[画像]]&".png" -> image/acetate.png | F4: =テーブル1[[#This Row],[リンク]] -> https://cloudcatch1224.wixsite.com/godsfoot | G4: =SUBSTITUTE(テーブル1[[#This Row],[作品タグ]]," ","|") -> #神様の足元 | H4: =テーブル1[[#This Row],[性別]]&"" -> 男性 | I4: =テーブル1[[#This Row],[種族タグ]]&"" -> 人間|機械 | J4: =テーブル1[[#This Row],[職業タグ]]&"" -> 機械整備士 | K4: =テーブル1[[#This Row],[小物タグ]]&"" | L4: =テーブル1[[#This Row],[ワンポイントタグ]]&"" -> 角(ツノ)|羽|尻尾
A5: =テーブル1[[#This Row],[番号]] -> 4 | B5: =テーブル1[[#This Row],[名前]] -> 足立レイ | C5: =テーブル1[[#This Row],[なまえ]] -> あだち れい | D5: =テーブル1[[#This Row],[Name]] -> Adachi Rei | E5: ="image/"&テーブル1[[#This Row],[画像]]&".png" -> image/adachi-rei.png | F5: =テーブル1[[#This Row],[リンク]] -> https://mechanicalgirl.jp | G5: =SUBSTITUTE(テーブル1[[#This Row],[作品タグ]]," ","|") -> #足立レイ | H5: =テーブル1[[#This Row],[性別]]&"" -> 女性 | I5: =テーブル1[[#This Row],[種族タグ]]&"" -> 機械 | J5: =テーブル1[[#This Row],[職業タグ]]&"" | K5: =テーブル1[[#This Row],[小物タグ]]&"" -> イヤーユニット | L5: =テーブル1[[#This Row],[ワンポイントタグ]]&""
A6: =テーブル1[[#This Row],[番号]] -> 5 | B6: =テーブル1[[#This Row],[名前]] -> 花鶏音ひわ | C6: =テーブル1[[#This Row],[なまえ]] -> あとりね ひわ | D6: =テーブル1[[#This Row],[Name]] -> Atorine Hiwa | E6: ="image/"&テーブル1[[#This Row],[画像]]&".png" -> image/atorine-hiwa.png | F6: =テーブル1[[#This Row],[リンク]] -> https://torinosu-hikikomori.jimdofree.com | G6: =SUBSTITUTE(テーブル1[[#This Row],[作品タグ]]," ","|") -> #ひわわーアラート | H6: =テーブル1[[#This Row],[性別]]&"" -> 女性 | I6: =テーブル1[[#This Row],[種族タグ]]&"" -> 鳥 | J6: =テーブル1[[#This Row],[職業タグ]]&"" | K6: =テーブル1[[#This Row],[小物タグ]]&"" -> マスク | L6: =テーブル1[[#This Row],[ワンポイントタグ]]&"" -> 羽
A7: =テーブル1[[#This Row],[番号]] -> 6 | B7: =テーブル1[[#This Row],[名前]] -> Adol | C7: =テーブル1[[#This Row],[なまえ]] -> あどる | D7: =テーブル1[[#This Row],[Name]] -> Adol | E7: ="image/"&テーブル1[[#This Row],[画像]]&".png" -> image/adol.png | F7: =テーブル1[[#This Row],[リンク]] -> https://kuroi9603.wixsite.com/delu-lab-south | G7: =SUBSTITUTE(テーブル1[[#This Row],[作品タグ]]," ","|") -> #でるらぼ | H7: =テーブル1[[#This Row],[性別]]&"" -> 女性 | I7: =テーブル1[[#This Row],[種族タグ]]&"" -> 人間 | J7: =テーブル1[[#This Row],[職業タグ]]&"" | K7: =テーブル1[[#This Row],[小物タグ]]&"" | L7: =テーブル1[[#This Row],[ワンポイントタグ]]&""
A8: =テーブル1[[#This Row],[番号]] -> 7 | B8: =テーブル1[[#This Row],[名前]] -> アニマ・ライツハット | C8: =テーブル1[[#This Row],[なまえ]] -> あにま らいつはっと | D8: =テーブル1[[#This Row],[Name]] -> Anima Raituhatto | E8: ="image/"&テーブル1[[#This Row],[画像]]&".png" -> image/anima-raituhatto.png | F8: =テーブル1[[#This Row],[リンク]] -> https://seirentoybox.jimdofree.com | G8: =SUBSTITUTE(テーブル1[[#This Row],[作品タグ]]," ","|") -> #セレソー作 | H8: =テーブル1[[#This Row],[性別]]&"" -> 無性別 | I8: =テーブル1[[#This Row],[種族タグ]]&"" -> バーチャル | J8: =テーブル1[[#This Row],[職業タグ]]&"" | K8: =テーブル1[[#This Row],[小物タグ]]&"" -> 眼鏡 | L8: =テーブル1[[#This Row],[ワンポイントタグ]]&"" -> オッドアイ
A9: =テーブル1[[#This Row],[番号]] -> 8 | B9: =テーブル1[[#This Row],[名前]] -> 天使ふあわ | C9: =テーブル1[[#This Row],[なまえ]] -> あまつか ふあわ | D9: =テーブル1[[#This Row],[Name]] -> Amatsuka Fuawa | E9: ="image/"&テーブル1[[#This Row],[画像]]&".png" -> image/amatsuka-fuawa.png | F9: =テーブル1[[#This Row],[リンク]] -> https://utausuzuminnya.jimdofree.com | G9: =SUBSTITUTE(テーブル1[[#This Row],[作品タグ]]," ","|") -> #ふあわあーと | H9: =テーブル1[[#This Row],[性別]]&"" -> 女性 | I9: =テーブル1[[#This Row],[種族タグ]]&"" -> 人間|天使 | J9: =テーブル1[[#This Row],[職業タグ]]&"" | K9: =テーブル1[[#This Row],[小物タグ]]&"" | L9: =テーブル1[[#This Row],[ワンポイントタグ]]&"" -> 羽
A10: =テーブル1[[#This Row],[番号]] -> 9 | B10: =テーブル1[[#This Row],[名前]] -> 雨音うさぎ | C10: =テーブル1[[#This Row],[なまえ]] -> あまね うさぎ | D10: =テーブル1[[#This Row],[Name]] -> Amane Usagi | E10: ="image/"&テーブル1[[#This Row],[画像]]&".png" -> image/amane-usagi.png | F10: =テーブル1[[#This Row],[リンク]] -> https://sabaneko.amebaownd.com | G10: =SUBSTITUTE(テーブル1[[#This Row],[作品タグ]]," ","|") -> #雨音うさぎ | H10: =テーブル1[[#This Row],[性別]]&"" -> 女性 | I10: =テーブル1[[#This Row],[種族タグ]]&"" -> 人間 | J10: =テーブル1[[#This Row],[職業タグ]]&"" | K10: =テーブル1[[#This Row],[小物タグ]]&"" -> 動物 | L10: =テーブル1[[#This Row],[ワンポイントタグ]]&"" -> 渦巻き目、アホ毛
A11: =テーブル1[[#This Row],[番号]] -> 10 | B11: =テーブル1[[#This Row],[名前]] -> 怪子奇 | C11: =テーブル1[[#This Row],[なまえ]] -> あやしき | D11: =テーブル1[[#This Row],[Name]] -> Ayashiki | E11: ="image/"&テーブル1[[#This Row],[画像]]&".png" -> image/ayashiki.png | F11: =テーブル1[[#This Row],[リンク]] -> https://inudanuki.wixsite.com/gottaniomotyabako | G11: =SUBSTITUTE(テーブル1[[#This Row],[作品タグ]]," ","|") -> #煮バコ | H11: =テーブル1[[#This Row],[性別]]&"" -> 男性 | I11: =テーブル1[[#This Row],[種族タグ]]&"" -> 故人|幽霊 | J11: =テーブル1[[#This Row],[職業タグ]]&"" | K11: =テーブル1[[#This Row],[小物タグ]]&"" | L11: =テーブル1[[#This Row],[ワンポイントタグ]]&"" -> ツートンカラー
A12: =テーブル1[[#This Row],[番号]] -> 11 | B12: =テーブル1[[#This Row],[名前]] -> 泡沫紬 | C12: =テーブル1[[#This Row],[なまえ]] -> うたかた つむぎ | D12: =テーブル1[[#This Row],[Name]] -> Utakata Tsumugi | E12: ="image/"&テーブル1[[#This Row],[画像]]&".png" -> image/utakata-tsumugi.png | F12: =テーブル1[[#This Row],[リンク]] -> https://tourist100f.wixsite.com/utakata-kosyo | G12: =SUBSTITUTE(テーブル1[[#This Row],[作品タグ]]," ","|") -> #泡沫古書店 | H12: =テーブル1[[#This Row],[性別]]&"" -> 女性 | I12: =テーブル1[[#This Row],[種族タグ]]&"" -> 人間 | J12: =テーブル1[[#This Row],[職業タグ]]&"" -> 書店員 | K12: =テーブル1[[#This Row],[小物タグ]]&"" -> 眼鏡 | L12: =テーブル1[[#This Row],[ワンポイントタグ]]&""
A13: =テーブル1[[#This Row],[番号]] -> 12 | B13: =テーブル1[[#This Row],[名前]] -> 唄音ウタ(デフォ子) | C13: =テーブル1[[#This Row],[なまえ]] -> うたね うた(でふぉこ) | D13: =テーブル1[[#This Row],[Name]] -> Utane Uta(Defoko) | E13: ="image/"&テーブル1[[#This Row],[画像]]&".png" -> image/utane-uta(defoko).png | F13: =テーブル1[[#This Row],[リンク]] -> - | G13: =SUBSTITUTE(テーブル1[[#This Row],[作品タグ]]," ","|") -> #デフォ子 | H13: =テーブル1[[#This Row],[性別]]&"" -> 女性 | I13: =テーブル1[[#This Row],[種族タグ]]&"" | J13: =テーブル1[[#This Row],[職業タグ]]&"" | K13: =テーブル1[[#This Row],[小物タグ]]&"" -> ヘッドセット | L13: =テーブル1[[#This Row],[ワンポイントタグ]]&""
... A233: =テーブル1[[#This Row],[番号]] -> 232 | B233: =テーブル1[[#This Row],[名前]] -> 鳴上キョウ | C233: =テーブル1[[#This Row],[なまえ]] -> なるかみ きょう | D233: =テーブル1[[#This Row],[Name]] -> Narukami Kyou | E233: ="image/"&テーブル1[[#This Row],[画像]]&".png" -> image/narukami-kyou.png | F233: =テーブル1[[#This Row],[リンク]] -> https://sites.google.com/view/arcobaleno-utau/home | G233: =SUBSTITUTE(テーブル1[[#This Row],[作品タグ]]," ","|") -> 鳴上キョウ(UTAU) | H233: =テーブル1[[#This Row],[性別]]&"" -> 男性 | I233: =テーブル1[[#This Row],[種族タグ]]&"" -> 人間 | J233: =テーブル1[[#This Row],[職業タグ]]&"" | K233: =テーブル1[[#This Row],[小物タグ]]&"" | L233: =テーブル1[[#This Row],[ワンポイントタグ]]&""
